Traceback (most recent call last):
  File "/ccs/home/lsawade/dtn_miniconda3/envs/gf-dtn/lib/python3.11/site-packages/nnodes/node.py", line 320, in _exec_task
    await result
  File "/ccs/home/lsawade/dtn_miniconda3/envs/gf-dtn/lib/python3.11/site-packages/nnodes/mpiexec.py", line 242, in mpiexec
    raise err
  File "/ccs/home/lsawade/dtn_miniconda3/envs/gf-dtn/lib/python3.11/site-packages/nnodes/mpiexec.py", line 214, in mpiexec
    raise RuntimeError(d.read(f'{fname}.error'))
RuntimeError: Traceback (most recent call last):
  File "/ccs/home/lsawade/dtn_miniconda3/envs/gf-dtn/lib/python3.11/site-packages/nnodes/mpi.py", line 94, in <module>
    _call(0, 0)
  File "/ccs/home/lsawade/dtn_miniconda3/envs/gf-dtn/lib/python3.11/site-packages/nnodes/mpi.py", line 33, in _call
    from mpi4py.MPI import COMM_WORLD as comm
ModuleNotFoundError: No module named 'mpi4py'


Traceback (most recent call last):
  File "/ccs/home/lsawade/dtn_miniconda3/envs/gf-dtn/lib/python3.11/site-packages/nnodes/node.py", line 320, in _exec_task
    await result
  File "/ccs/home/lsawade/dtn_miniconda3/envs/gf-dtn/lib/python3.11/site-packages/nnodes/mpiexec.py", line 242, in mpiexec
    raise err
  File "/ccs/home/lsawade/dtn_miniconda3/envs/gf-dtn/lib/python3.11/site-packages/nnodes/mpiexec.py", line 214, in mpiexec
    raise RuntimeError(d.read(f'{fname}.error'))
RuntimeError: Traceback (most recent call last):
  File "/ccs/home/lsawade/dtn_miniconda3/envs/gf-dtn/lib/python3.11/site-packages/nnodes/mpi.py", line 94, in <module>
    _call(0, 0)
  File "/ccs/home/lsawade/dtn_miniconda3/envs/gf-dtn/lib/python3.11/site-packages/nnodes/mpi.py", line 33, in _call
    from mpi4py.MPI import COMM_WORLD as comm
ModuleNotFoundError: No module named 'mpi4py'


Traceback (most recent call last):
  File "/ccs/home/lsawade/dtn_miniconda3/envs/gf-dtn/lib/python3.11/site-packages/nnodes/node.py", line 320, in _exec_task
    await result
  File "/ccs/home/lsawade/dtn_miniconda3/envs/gf-dtn/lib/python3.11/site-packages/nnodes/mpiexec.py", line 242, in mpiexec
    raise err
  File "/ccs/home/lsawade/dtn_miniconda3/envs/gf-dtn/lib/python3.11/site-packages/nnodes/mpiexec.py", line 214, in mpiexec
    raise RuntimeError(d.read(f'{fname}.error'))
RuntimeError: Traceback (most recent call last):
  File "/ccs/home/lsawade/dtn_miniconda3/envs/gf-dtn/lib/python3.11/site-packages/nnodes/mpi.py", line 94, in <module>
    _call(0, 0)
  File "/ccs/home/lsawade/dtn_miniconda3/envs/gf-dtn/lib/python3.11/site-packages/nnodes/mpi.py", line 33, in _call
    from mpi4py.MPI import COMM_WORLD as comm
ModuleNotFoundError: No module named 'mpi4py'


Traceback (most recent call last):
  File "/ccs/home/lsawade/dtn_miniconda3/envs/gf-dtn/lib/python3.11/site-packages/nnodes/node.py", line 320, in _exec_task
    await result
  File "/ccs/home/lsawade/dtn_miniconda3/envs/gf-dtn/lib/python3.11/site-packages/nnodes/mpiexec.py", line 242, in mpiexec
    raise err
  File "/ccs/home/lsawade/dtn_miniconda3/envs/gf-dtn/lib/python3.11/site-packages/nnodes/mpiexec.py", line 214, in mpiexec
    raise RuntimeError(d.read(f'{fname}.error'))
RuntimeError: Traceback (most recent call last):
  File "/ccs/home/lsawade/dtn_miniconda3/envs/gf-dtn/lib/python3.11/site-packages/nnodes/mpi.py", line 94, in <module>
    _call(0, 0)
  File "/ccs/home/lsawade/dtn_miniconda3/envs/gf-dtn/lib/python3.11/site-packages/nnodes/mpi.py", line 33, in _call
    from mpi4py.MPI import COMM_WORLD as comm
ModuleNotFoundError: No module named 'mpi4py'


